# 에러 처리

- 출처 [모던 자바스크립트 Deep Dive](http://www.yes24.com/Product/Goods/92742567?OzSrank=1)을 보고 정리한 내용입니다.

<br>

## 1. 에러 처리의 필요성

<br>

에러는 언제나 발생할 수 있다. 발생한 에러에 대해 대처하지 않고 방치하면 프로그램은 강제 종료된다.

```jsx
console.log('[Start]');

foo(); // ReferenceError: foo is not defined
// 발생한 에러를 방치하면 프로그램은 강제 종료된다.

// 에러에 의해 프로그램이 강제 종료되어 아래 코드는 실행되지 않는다.
console.log('[End]');
```

<br>

```jsx
console.log('[Start]');

try {
  foo();
} catch (error) {
  console.error('[에러 발생]', error);
  // [에러 발생] ReferenceError: foo is not defined
}

// 발생한 에러에 적절한 대응을 하면 프로그램이 강제 종료되지 않는다.
console.log('[End]');
```

try…catch 문을 사용하면 try문안에서 발생한 에러문을 catch문에서 실행한다.

프로그램이 강제 종료되지 않고 catch문 다음 코드도 실행해준다.

<br>

이처럼 에러나 예외적인 상황에 대응하지 않으면 프로그램은 강제 종료될 것이다. 

에러나 예외적인 상황은 너무나 다양하기 때문에 아무런 조치 없이 프로그램이 강제 종료된다면 원인을 파악하여 대응하기 어렵다.

따라서 우리가 작성한 코드에서는 언제나 에러나 예외적인 상황이 발생할 수 있다는 것을 전제하고 이에 대응하는 코드를 작성하는 것이 중요하다.

<br>

## 2. try...catch...finally문

<br>

```jsx
try {
  // 실행할 코드(에러가 발생할 가능성이 있는 코드)
} catch (err) {
  // try 코드 블록에서 에러가 발생하면 이 코드 블록의 코드가 실행된다.
  // err에는 try 코드 블록에서 발생한 Error 객체가 전달된다.
} finally {
  // 에러 발생과 상관없이 반드시 한 번 실행된다.
}
```

<br>

**try** 코드 블록에 포함된 문 중에서 에러가 발생하면 발생한 에러는 catch 문의 err 변수에 전달되고 catch 코드 블록이 실행된다.

<br>

**catch** 문의 err 변수(변수 이름은 무엇이든 상관없다)는 try 코드 블록에 포함된 문 중에서 에러가 발생하면 생성되고 되고 catch 코드 블록에서만 유효하다.

<br>

**finally** 코드 블록은 에러 발생과 상관없이 반드시 한 번 실행된다.

<br>

```jsx
console.log('[Start]');

try {
  // 실행할 코드(에러가 발생할 가능성이 있는 코드)
  foo();
} catch (err) {
  // try 코드 블록에서 에러가 발생하면 이 코드 블록의 코드가 실행된다.
  // err에는 try 코드 블록에서 발생한 Error 객체가 전달된다.
  console.error(err); // ReferenceError: foo is not defined
} finally {
  // 에러 발생과 상관없이 반드시 한 번 실행된다.
  console.log('finally');
}

// try...catch...finally 문으로 에러를 처리하면 프로그램이 강제 종료되지 않는다.
console.log('[End]');
```

<br>

## 3. Error 객체

<br>

Error 생성자 함수는 에러 객체를 생성한다.

Error 생성자 함수에는 에러를 상세히 설명하는 에러 메시지를 인수로 전달할 수 있다.

```jsx
const error = new Error('invalid');
```

<br>

Error 생성자 함수가 생성한 에러 객체는 

**message 프로퍼티**와 **stack 프로퍼티**를 갖는다.

<br>

**message 프로퍼티** 의 값은 Error 생성자 함수에 인수로 전달한 **에러 메시지** 이고,

<br>

**stack 프로퍼티** 의 값은 에러를 발생시킨 콜 스택의 **호출 정보를 나타내는 문자열** 이며 디버깅 목적으로 사용한다.

<br>

Error 생성자 함수를 포함해 **7가지**의 에러 객체를 생성할 수 있다.

<br>

## 4. throw 문

<br>

Error 생성자 함수로 에러 객체를 생성한다고 에러가 발생하는 것은 아니다.

```jsx
try {
  // 에러 객체를 생성한다고 에러가 발생하는 것은 아니다.
  new Error('something wrong');
} catch (error) {
  console.log(error);
}
```

<br>

에러를 발생시키려면 try 코드 블록에서 throw 문으로 에러 객체를 던져야 한다.

```jsx
try {
  // 에러 객체를 던지면 catch 코드 블록이 실행되기 시작한다.
  throw new Error('something wrong');
} catch (error) {
  console.log(error);
}
```

<br>

1. catch 문에 들어서게 되면 error 변수가 생성된다.
2. 던져진 에러 객체는 catch 문의 error 변수에 할당된다.

<br>

## 5. 에러의 전파

<br>

에러는 호출자(caller) 방향으로 전파된다.

콜 스택의 아래 방향(실행 중인 실행 컨텍스트가 푸시되기 직전에 푸시된 실행 컨텍스트 방향)으로 전파된다.

```jsx
const foo = () => {
  throw Error('foo에서 발생한 에러'); // ④
};

const bar = () => {
  foo(); // ③
};

const baz = () => {
  bar(); // ②
};

try {
  baz(); // ①
} catch (err) {
  console.error(err);
}
```

<br>

throw된 에러를 캐치하여 적절히 대응하면 프로그램을 강제 종료시키지 않고 코드의 실행 흐름을 복구할 수 있다. 

throw된 에러를 어디에서도 캐치하지 않으면 프로그램은 강제 종료된다.

<br>

**주의!**

주의할 것은 비동기 함수인 setTimeout이나 프로미스 후속 처리 메서드의 콜백 함수는 호출자가 없다는 것이다.

<br>

**설명**

setTimeout이나 프로미스 후속 처리 메서드의 콜백 함수는 태스크 큐나 마이크로태스크 큐에 일시 저장되었다가 콜 스택이 비면 이벤트 루프에 의해 콜 스택으로 푸시되어 실행된다. 

이때 콜 스택에 푸시된 콜백 함수의 실행 컨텍스트는 콜 스택의 가장 하부에 존재하게 된다.